Workbook

Sheet Como preencher
A1: Tabela de preços ORYA · como preencher
A3: Desconto padrão no Pix/dinheiro | B3: 0.1 | C3: Usado em todas as linhas da tabela, a não ser que você troque o desconto na própria linha.
A4: Parcelas sem juros (padrão) | B4: 10 | C4: Número padrão de parcelas no cartão.
A7: O QUE PREENCHER (aba 'Tabela de preços'):
A8: • Células AMARELAS são para você preencher: Valor cheio, Parcelas, Desconto Pix (se for diferente do padrão) e a coluna 'O bot pode informar?'.
A9: • Texto AZUL = valor digitado (entrada). Texto PRETO = fórmula calculada sozinha (não precisa mexer).
A10: • 'Valor da parcela' e 'Valor no Pix/dinheiro' são calculados automaticamente.
A11: • 'O bot pode informar?': Sim = a Aurora passa o valor na conversa; Só na avaliação = ela não fala valor e convida para a avaliação.
A12: • Procedimento que vocês não fazem: escreva 'Não fazemos' na coluna 'O bot pode informar?' (ou apague a linha).
A13: • Pode acrescentar linhas no final de cada categoria, copiando uma linha de cima (assim as fórmulas vêm junto).
A14: • As linhas já preenchidas vieram do que você me passou na conversa (28/10/2026). Confira.
A16: Quando terminar, me devolva o arquivo que eu atualizo o bot.

Sheet Tabela de preços
A1: Tabela de preços ORYA
A2: Amarelo = preencher. Azul = digitado. Preto = calculado. Veja a aba 'Como preencher'.
A4: Categoria | B4: Procedimento | C4: Unidade de venda | D4: Valor cheio (R$) | E4: Parcelas sem juros | F4: Valor da parcela (R$) | G4: Desconto Pix/dinheiro | H4: Valor no Pix/dinheiro (R$) | I4: O bot pode informar? | J4: Observações (sessões indicadas, o que inclui, pacote)
A5: Avaliação | B5: Avaliação com a Dra. Danielly | C5: consulta | D5: 200 | E5: 1 | F5: =IF(OR(D5="",E5=0),"",D5/E5) -> 200 | G5: 0 | H5: =IF(D5="","",D5*(1-G5)) -> 200 | I5: Sim | J5: Paga antecipada (Pix ou link de cartão). 100% abatida no procedimento fechado; falta não devolve.
A6: Toxina botulínica | B6: Botox terço superior | C6: aplicação | D6: 1100 | E6: ='Como preencher'!$B$4 -> 10 | F6: =IF(OR(D6="",E6=0),"",D6/E6) -> 110 | G6: ='Como preencher'!$B$3 -> 0.1 | H6: =IF(D6="","",D6*(1-G6)) -> 990 | I6: Sim | J6: Testa, glabela e pés de galinha. Retorno em 15 dias incluso.
A7: Toxina botulínica | B7: Botox face completa | C7: aplicação | D7: 1400 | E7: ='Como preencher'!$B$4 -> 10 | F7: =IF(OR(D7="",E7=0),"",D7/E7) -> 140 | G7: ='Como preencher'!$B$3 -> 0.1 | H7: =IF(D7="","",D7*(1-G7)) -> 1260 | I7: Sim | J7: Retorno em 15 dias incluso.
A8: Toxina botulínica | B8: Plano Olhar Leve Anual (botox terço superior) | C8: plano 4 aplicações/12 meses | D8: 3080 | E8: ='Como preencher'!$B$4 -> 10 | F8: =IF(OR(D8="",E8=0),"",D8/E8) -> 308 | G8: 0 | H8: =IF(D8="","",D8*(1-G8)) -> 3080 | I8: Sim | J8: 30% menor que 4 avulsas. Mesmo valor em qualquer forma de pagamento.
A9: Toxina botulínica | B9: Plano anual face completa | C9: plano | E9: ='Como preencher'!$B$4 -> 10 | F9: =IF(OR(D9="",E9=0),"",D9/E9) | G9: ='Como preencher'!$B$3 -> 0.1 | H9: =IF(D9="","",D9*(1-G9)) | I9: Só na avaliação | J9: Depende da avaliação da Dra.
A10: Toxina botulínica | B10: Botox para bruxismo (masseter) | C10: aplicação | E10: ='Como preencher'!$B$4 -> 10 | F10: =IF(OR(D10="",E10=0),"",D10/E10) | G10: ='Como preencher'!$B$3 -> 0.1 | H10: =IF(D10="","",D10*(1-G10))
A11: Toxina botulínica | B11: Botox para sorriso gengival | C11: aplicação | E11: ='Como preencher'!$B$4 -> 10 | F11: =IF(OR(D11="",E11=0),"",D11/E11) | G11: ='Como preencher'!$B$3 -> 0.1 | H11: =IF(D11="","",D11*(1-G11))
A12: Toxina botulínica | B12: Botox pescoço (Nefertiti) | C12: aplicação | E12: ='Como preencher'!$B$4 -> 10 | F12: =IF(OR(D12="",E12=0),"",D12/E12) | G12: ='Como preencher'!$B$3 -> 0.1 | H12: =IF(D12="","",D12*(1-G12))
A13: Toxina botulínica | B13: Botox para hiperidrose (suor axilar) | C13: aplicação | E13: ='Como preencher'!$B$4 -> 10 | F13: =IF(OR(D13="",E13=0),"",D13/E13) | G13: ='Como preencher'!$B$3 -> 0.1 | H13: =IF(D13="","",D13*(1-G13))
A14: Preenchimento e harmonização | B14: Preenchimento labial 1 ml | C14: 1 ml | D14: 1100 | E14: ='Como preencher'!$B$4 -> 10 | F14: =IF(OR(D14="",E14=0),"",D14/E14) -> 110 | G14: ='Como preencher'!$B$3 -> 0.1 | H14: =IF(D14="","",D14*(1-G14)) -> 990 | I14: Sim
A15: Preenchimento e harmonização | B15: Harmonização facial | C15: plano personalizado | E15: ='Como preencher'!$B$4 -> 10 | F15: =IF(OR(D15="",E15=0),"",D15/E15) | G15: ='Como preencher'!$B$3 -> 0.1 | H15: =IF(D15="","",D15*(1-G15)) | I15: Só na avaliação | J15: Valor só após avaliação.
A16: Preenchimento e harmonização | B16: Preenchimento malar (maçãs do rosto) | C16: por ml | E16: ='Como preencher'!$B$4 -> 10 | F16: =IF(OR(D16="",E16=0),"",D16/E16) | G16: ='Como preencher'!$B$3 -> 0.1 | H16: =IF(D16="","",D16*(1-G16)) | I16: Só na avaliação
A17: Preenchimento e harmonização | B17: Rinomodelação (nariz) | C17: procedimento | E17: ='Como preencher'!$B$4 -> 10 | F17: =IF(OR(D17="",E17=0),"",D17/E17) | G17: ='Como preencher'!$B$3 -> 0.1 | H17: =IF(D17="","",D17*(1-G17)) | I17: Só na avaliação
A18: Preenchimento e harmonização | B18: Preenchimento de olheiras | C18: procedimento | E18: ='Como preencher'!$B$4 -> 10 | F18: =IF(OR(D18="",E18=0),"",D18/E18) | G18: ='Como preencher'!$B$3 -> 0.1 | H18: =IF(D18="","",D18*(1-G18))
A19: Preenchimento e harmonização | B19: Preenchimento de mandíbula | C19: por ml | E19: ='Como preencher'!$B$4 -> 10 | F19: =IF(OR(D19="",E19=0),"",D19/E19) | G19: ='Como preencher'!$B$3 -> 0.1 | H19: =IF(D19="","",D19*(1-G19)) | I19: Só na avaliação
A20: Preenchimento e harmonização | B20: Preenchimento de mento (queixo) | C20: por ml | E20: ='Como preencher'!$B$4 -> 10 | F20: =IF(OR(D20="",E20=0),"",D20/E20) | G20: ='Como preencher'!$B$3 -> 0.1 | H20: =IF(D20="","",D20*(1-G20)) | I20: Só na avaliação
A21: Preenchimento e harmonização | B21: Preenchimento de sulco nasogeniano (bigode chinês) | C21: por ml | E21: ='Como preencher'!$B$4 -> 10 | F21: =IF(OR(D21="",E21=0),"",D21/E21) | G21: ='Como preencher'!$B$3 -> 0.1 | H21: =IF(D21="","",D21*(1-G21))
A22: Preenchimento e harmonização | B22: Preenchimento de têmporas | C22: por ml | E22: ='Como preencher'!$B$4 -> 10 | F22: =IF(OR(D22="",E22=0),"",D22/E22) | G22: ='Como preencher'!$B$3 -> 0.1 | H22: =IF(D22="","",D22*(1-G22))
A23: Preenchimento e harmonização | B23: Hidragloss (hidratação labial) | C23: sessão | E23: ='Como preencher'!$B$4 -> 10 | F23: =IF(OR(D23="",E23=0),"",D23/E23) | G23: ='Como preencher'!$B$3 -> 0.1 | H23: =IF(D23="","",D23*(1-G23))
A24: Bioestimuladores e qualidade de pele | B24: Bioestimulador de colágeno facial (Sculptra / Radiesse) | C24: frasco/seringa | E24: ='Como preencher'!$B$4 -> 10 | F24: =IF(OR(D24="",E24=0),"",D24/E24) | G24: ='Como preencher'!$B$3 -> 0.1 | H24: =IF(D24="","",D24*(1-G24)) | I24: Só na avaliação | J24: Valor só após avaliação.
A25: Bioestimuladores e qualidade de pele | B25: Bioestimulador corporal | C25: frasco | E25: ='Como preencher'!$B$4 -> 10 | F25: =IF(OR(D25="",E25=0),"",D25/E25) | G25: ='Como preencher'!$B$3 -> 0.1 | H25: =IF(D25="","",D25*(1-G25)) | I25: Só na avaliação | J25: Valor só após avaliação.
A26: Bioestimuladores e qualidade de pele | B26: Skinbooster | C26: sessão | E26: ='Como preencher'!$B$4 -> 10 | F26: =IF(OR(D26="",E26=0),"",D26/E26) | G26: ='Como preencher'!$B$3 -> 0.1 | H26: =IF(D26="","",D26*(1-G26))
A27: Bioestimuladores e qualidade de pele | B27: Profhilo | C27: sessão | E27: ='Como preencher'!$B$4 -> 10 | F27: =IF(OR(D27="",E27=0),"",D27/E27) | G27: ='Como preencher'!$B$3 -> 0.1 | H27: =IF(D27="","",D27*(1-G27))
A28: Bioestimuladores e qualidade de pele | B28: Fios de PDO lisos | C28: procedimento | E28: ='Como preencher'!$B$4 -> 10 | F28: =IF(OR(D28="",E28=0),"",D28/E28) | G28: ='Como preencher'!$B$3 -> 0.1 | H28: =IF(D28="","",D28*(1-G28))
A29: Bioestimuladores e qualidade de pele | B29: Fios de PDO espiculados (sustentação) | C29: procedimento | E29: ='Como preencher'!$B$4 -> 10 | F29: =IF(OR(D29="",E29=0),"",D29/E29) | G29: ='Como preencher'!$B$3 -> 0.1 | H29: =IF(D29="","",D29*(1-G29))
A30: Bioestimuladores e qualidade de pele | B30: Lipo de papada enzimática | C30: sessão | E30: ='Como preencher'!$B$4 -> 10 | F30: =IF(OR(D30="",E30=0),"",D30/E30) | G30: ='Como preencher'!$B$3 -> 0.1 | H30: =IF(D30="","",D30*(1-G30)) | J30: Quantas sessões em média?
A31: Bioestimuladores e qualidade de pele | B31: Enzimas faciais | C31: sessão | E31: ='Como preencher'!$B$4 -> 10 | F31: =IF(OR(D31="",E31=0),"",D31/E31) | G31: ='Como preencher'!$B$3 -> 0.1 | H31: =IF(D31="","",D31*(1-G31))
A32: Tecnologias faciais | B32: Ultraformer face | C32: sessão | E32: ='Como preencher'!$B$4 -> 10 | F32: =IF(OR(D32="",E32=0),"",D32/E32) | G32: ='Como preencher'!$B$3 -> 0.1 | H32: =IF(D32="","",D32*(1-G32))
A33: Tecnologias faciais | B33: Ultraformer papada | C33: sessão | E33: ='Como preencher'!$B$4 -> 10 | F33: =IF(OR(D33="",E33=0),"",D33/E33) | G33: ='Como preencher'!$B$3 -> 0.1 | H33: =IF(D33="","",D33*(1-G33))
A34: Tecnologias faciais | B34: Ultraformer olhos/pálpebras | C34: sessão | E34: ='Como preencher'!$B$4 -> 10 | F34: =IF(OR(D34="",E34=0),"",D34/E34) | G34: ='Como preencher'!$B$3 -> 0.1 | H34: =IF(D34="","",D34*(1-G34))
A35: Tecnologias faciais | B35: Hipro | C35: sessão | E35: ='Como preencher'!$B$4 -> 10 | F35: =IF(OR(D35="",E35=0),"",D35/E35) | G35: ='Como preencher'!$B$3 -> 0.1 | H35: =IF(D35="","",D35*(1-G35))
A36: Tecnologias faciais | B36: Lavieen | C36: sessão | E36: ='Como preencher'!$B$4 -> 10 | F36: =IF(OR(D36="",E36=0),"",D36/E36) | G36: ='Como preencher'!$B$3 -> 0.1 | H36: =IF(D36="","",D36*(1-G36))
A37: Tecnologias faciais | B37: Blefaroplastia sem corte (jato de plasma) | C37: 3 sessões | E37: ='Como preencher'!$B$4 -> 10 | F37: =IF(OR(D37="",E37=0),"",D37/E37) | G37: ='Como preencher'!$B$3 -> 0.1 | H37: =IF(D37="","",D37*(1-G37))
A38: Tecnologias faciais | B38: Radiofrequência facial | C38: sessão | E38: ='Como preencher'!$B$4 -> 10 | F38: =IF(OR(D38="",E38=0),"",D38/E38) | G38: ='Como preencher'!$B$3 -> 0.1 | H38: =IF(D38="","",D38*(1-G38))
A39: Pele | B39: Limpeza de pele | C39: sessão | D39: 150 | E39: ='Como preencher'!$B$4 -> 10 | F39: =IF(OR(D39="",E39=0),"",D39/E39) -> 15 | G39: ='Como preencher'!$B$3 -> 0.1 | H39: =IF(D39="","",D39*(1-G39)) -> 135 | I39: Sim
A40: Pele | B40: Microagulhamento | C40: sessão | E40: ='Como preencher'!$B$4 -> 10 | F40: =IF(OR(D40="",E40=0),"",D40/E40) | G40: ='Como preencher'!$B$3 -> 0.1 | H40: =IF(D40="","",D40*(1-G40))
A41: Pele | B41: Peeling químico | C41: sessão | E41: ='Como preencher'!$B$4 -> 10 | F41: =IF(OR(D41="",E41=0),"",D41/E41) | G41: ='Como preencher'!$B$3 -> 0.1 | H41: =IF(D41="","",D41*(1-G41))
...
